08:14:49 PM: DEBUG [logger_base.py:14] Mensaje a nivel debug
08:14:49 PM: INFO [logger_base.py:15] Mensaje a nivel info
08:14:49 PM: WARNING [logger_base.py:16] Mensaje a nivel de warning
08:14:49 PM: ERROR [logger_base.py:17] Mensaje a nivel de error
08:14:49 PM: CRITICAL [logger_base.py:18] Mensaje a nivel critico
07:29:14 PM: DEBUG [Persona.py:52] 
            Id Persona: 1, 
            Nombre: Juan,
            Apellido: Perez, 
            Email: jperez@mail.com
        
07:29:14 PM: DEBUG [Persona.py:56] 
            Id Persona: None, 
            Nombre: Juan,
            Apellido: Perez, 
            Email: jperez@mail.com
        
07:29:14 PM: DEBUG [Persona.py:59] 
            Id Persona: 1, 
            Nombre: None,
            Apellido: None, 
            Email: None
        
07:53:37 PM: ERROR [conexion.py:26] Ocurrió un error: connection to server at "127.0.0.1", port 5432 failed: FATAL:  database "test_db" does not exist

07:56:56 PM: DEBUG [conexion.py:23] Conexión exitosa: <connection object at 0x000002086F7B3120; dsn: 'user=postgres password=xxx dbname=test_bd host=127.0.0.1 port=5432', closed: 0>
07:56:56 PM: DEBUG [conexion.py:36] Se abrió correctamente el cursor: <cursor object at 0x000002086FDB3840; closed: 0>
08:00:54 PM: DEBUG [conexion.py:23] Conexión exitosa: <connection object at 0x000001D4ED203120; dsn: 'user=postgres password=xxx dbname=test_bd host=127.0.0.1 port=5432', closed: 0>
08:00:54 PM: DEBUG [conexion.py:36] Se abrió correctamente el cursor: <cursor object at 0x000001D4EDC13840; closed: 0>
